{"trial_id": "0", "hyperparameters": {"space": [{"class_name": "Choice", "config": {"name": "units", "default": 8, "conditions": [], "values": [8, 16, 32], "ordered": true}}], "values": {"units": 16}}, "metrics": {"metrics": {}}, "score": null, "best_step": 0, "status": "FAILED", "message": "Traceback (most recent call last):\n  File \"/home/rahul/.local/lib/python3.10/site-packages/keras_tuner/engine/base_tuner.py\", line 270, in _try_run_and_update_trial\n    self._run_and_update_trial(trial, *fit_args, **fit_kwargs)\n  File \"/home/rahul/.local/lib/python3.10/site-packages/keras_tuner/engine/base_tuner.py\", line 235, in _run_and_update_trial\n    results = self.run_trial(trial, *fit_args, **fit_kwargs)\n  File \"/home/rahul/.local/lib/python3.10/site-packages/keras_tuner/engine/tuner.py\", line 287, in run_trial\n    obj_value = self._build_and_fit_model(trial, *args, **copied_kwargs)\n  File \"/home/rahul/.local/lib/python3.10/site-packages/keras_tuner/engine/tuner.py\", line 214, in _build_and_fit_model\n    results = self.hypermodel.fit(hp, model, *args, **kwargs)\n  File \"/home/rahul/.local/lib/python3.10/site-packages/keras_tuner/engine/hypermodel.py\", line 144, in fit\n    return model.fit(*args, **kwargs)\n  File \"/usr/local/lib/python3.10/dist-packages/keras/utils/traceback_utils.py\", line 70, in error_handler\n    raise e.with_traceback(filtered_tb) from None\n  File \"/tmp/__autograph_generated_filerf28l3el.py\", line 15, in tf__train_function\n    retval_ = ag__.converted_call(ag__.ld(step_function), (ag__.ld(self), ag__.ld(iterator)), None, fscope)\nValueError: in user code:\n\n    File \"/usr/local/lib/python3.10/dist-packages/keras/engine/training.py\", line 1249, in train_function  *\n        return step_function(self, iterator)\n    File \"/usr/local/lib/python3.10/dist-packages/keras/engine/training.py\", line 1233, in step_function  **\n        outputs = model.distribute_strategy.run(run_step, args=(data,))\n    File \"/usr/local/lib/python3.10/dist-packages/keras/engine/training.py\", line 1222, in run_step  **\n        outputs = model.train_step(data)\n    File \"/usr/local/lib/python3.10/dist-packages/keras/engine/training.py\", line 1024, in train_step\n        loss = self.compute_loss(x, y, y_pred, sample_weight)\n    File \"/usr/local/lib/python3.10/dist-packages/keras/engine/training.py\", line 1082, in compute_loss\n        return self.compiled_loss(\n    File \"/usr/local/lib/python3.10/dist-packages/keras/engine/compile_utils.py\", line 265, in __call__\n        loss_value = loss_obj(y_t, y_p, sample_weight=sw)\n    File \"/usr/local/lib/python3.10/dist-packages/keras/losses.py\", line 152, in __call__\n        losses = call_fn(y_true, y_pred)\n    File \"/usr/local/lib/python3.10/dist-packages/keras/losses.py\", line 284, in call  **\n        return ag_fn(y_true, y_pred, **self._fn_kwargs)\n    File \"/usr/local/lib/python3.10/dist-packages/keras/losses.py\", line 1500, in mean_squared_error\n        return backend.mean(tf.math.squared_difference(y_pred, y_true), axis=-1)\n\n    ValueError: Dimensions must be equal, but are 30 and 46 for '{{node mean_squared_error/SquaredDifference}} = SquaredDifference[T=DT_FLOAT](mean_squared_error/remove_squeezable_dimensions/Squeeze, mean_squared_error/Cast)' with input shapes: [32,30], [32,46].\n\n"}